<?xml version="1.0" ?>
<robot name="roomac" xmlns:xacro="http://www.ros.org/wiki/xacro">

<xacro:include filename="$(find roomac_description)/urdf/materials.xacro" />
<xacro:include filename="$(find roomac_description)/urdf/roomac.trans" />
<xacro:include filename="$(find roomac_description)/urdf/roomac.gazebo" />

<link name="gripper_right_grip"/>
<joint name="right_grip" type="fixed">
  <origin rpy="0 0 0" xyz="0.0 0.0 -0.085"/>
  <parent link="gripper_right_1"/>
  <child link="gripper_right_grip"/>
</joint>

<link name="base_link">
  <inertial>
    <origin rpy="0 0 0" xyz="-0.13060699359614247 -1.269142483394603e-05 0.10737373059306837"/>
    <mass value="3.353734949059196"/>
    <inertia ixx="0.139756" ixy="-3e-06" ixz="0.003607" iyy="0.140028" iyz="1.7e-05" izz="0.11189"/>
  </inertial>
  <visual>
    <origin rpy="0 0 0" xyz="0 0 0"/>
    <geometry>
      <mesh filename="package://roomac_description/meshes/base_link.stl" scale="0.001 0.001 0.001"/>
    </geometry>
    <material name="silver"/>
  </visual>
  <collision>
    <origin rpy="0 0 0" xyz="0 0 0"/>
    <geometry>
      <mesh filename="package://roomac_description/meshes/base_link.stl" scale="0.001 0.001 0.001"/>
    </geometry>
  </collision>
</link>

<link name="right_wheel_hub_1">
  <inertial>
    <origin rpy="0 0 0" xyz="-1.789765202460103e-06 0.012712108125801563 3.1361035185462073e-06"/>
    <mass value="0.09451094240372128"/>
    <inertia ixx="5e-05" ixy="0.0" ixz="0.0" iyy="8.5e-05" iyz="-0.0" izz="5e-05"/>
  </inertial>
  <visual>
    <origin rpy="0 0 0" xyz="-0.0 0.2429 0.0"/>
    <geometry>
      <mesh filename="package://roomac_description/meshes/right_wheel_hub_1.stl" scale="0.001 0.001 0.001"/>
    </geometry>
    <material name="silver"/>
  </visual>
  <collision>
    <origin rpy="0 0 0" xyz="-0.0 0.2429 0.0"/>
    <geometry>
      <mesh filename="package://roomac_description/meshes/right_wheel_hub_1.stl" scale="0.001 0.001 0.001"/>
    </geometry>
  </collision>
</link>

<link name="right_caster_1">
  <inertial>
    <origin rpy="0 0 0" xyz="-0.020793104918766903 -0.0009180067931599534 -0.11995837555497461"/>
    <mass value="1.2807118618501256"/>
    <inertia ixx="0.001622" ixy="-2e-06" ixz="-0.000322" iyy="0.002002" iyz="-8e-06" izz="0.000685"/>
  </inertial>
  <visual>
    <origin rpy="0 0 0" xyz="0.2985 0.16 -0.0275"/>
    <geometry>
      <mesh filename="package://roomac_description/meshes/right_caster_1.stl" scale="0.001 0.001 0.001"/>
    </geometry>
    <material name="silver"/>
  </visual>
  <collision>
    <origin rpy="0 0 0" xyz="0.2985 0.16 -0.0275"/>
    <geometry>
      <mesh filename="package://roomac_description/meshes/right_caster_1.stl" scale="0.001 0.001 0.001"/>
    </geometry>
  </collision>
</link>

<link name="shoulder_right_1">
  <inertial>
    <origin rpy="0 0 0" xyz="-0.0047122806080673735 -0.04192786474511692 0.007911548611731156"/>
    <mass value="2.326205944580142"/>
    <inertia ixx="0.002632" ixy="-0.000131" ixz="7.4e-05" iyy="0.002424" iyz="0.000318" izz="0.002843"/>
  </inertial>
  <visual>
    <origin rpy="0 0 0" xyz="0.11 0.144479 -0.9465"/>
    <geometry>
      <mesh filename="package://roomac_description/meshes/shoulder_right_1.stl" scale="0.001 0.001 0.001"/>
    </geometry>
    <material name="silver"/>
  </visual>
  <collision>
    <origin rpy="0 0 0" xyz="0.11 0.144479 -0.9465"/>
    <geometry>
      <mesh filename="package://roomac_description/meshes/shoulder_right_1.stl" scale="0.001 0.001 0.001"/>
    </geometry>
  </collision>
</link>

<link name="shoulder_elbow_right_1">
  <inertial>
    <origin rpy="0 0 0" xyz="0.026664587842609624 -1.986233008621774e-08 -0.08367829594075482"/>
    <mass value="1.1586288461581098"/>
    <inertia ixx="0.008424" ixy="-0.0" ixz="-2.9e-05" iyy="0.00832" iyz="-0.0" izz="0.000236"/>
  </inertial>
  <visual>
    <origin rpy="0 0 0" xyz="0.1365 0.243979 -0.9465"/>
    <geometry>
      <mesh filename="package://roomac_description/meshes/shoulder_elbow_right_1.stl" scale="0.001 0.001 0.001"/>
    </geometry>
    <material name="silver"/>
  </visual>
  <collision>
    <origin rpy="0 0 0" xyz="0.1365 0.243979 -0.9465"/>
    <geometry>
      <mesh filename="package://roomac_description/meshes/shoulder_elbow_right_1.stl" scale="0.001 0.001 0.001"/>
    </geometry>
  </collision>
</link>

<link name="elbow_wrist_right_1">
  <inertial>
    <origin rpy="0 0 0" xyz="-0.014013604508945773 -0.001176654247632164 -0.09047911672757791"/>
    <mass value="0.6237790413522313"/>
    <inertia ixx="0.001139" ixy="0.0" ixz="-2.9e-05" iyy="0.001204" iyz="-2e-05" izz="0.000118"/>
  </inertial>
  <visual>
    <origin rpy="0 0 0" xyz="0.094 0.243979 -0.745425"/>
    <geometry>
      <mesh filename="package://roomac_description/meshes/elbow_wrist_right_1.stl" scale="0.001 0.001 0.001"/>
    </geometry>
    <material name="silver"/>
  </visual>
  <collision>
    <origin rpy="0 0 0" xyz="0.094 0.243979 -0.745425"/>
    <geometry>
      <mesh filename="package://roomac_description/meshes/elbow_wrist_right_1.stl" scale="0.001 0.001 0.001"/>
    </geometry>
  </collision>
</link>

<link name="wrist_right_1">
  <inertial>
    <origin rpy="0 0 0" xyz="-0.02625691665766053 -0.0008947376423900366 -0.0234416265393953"/>
    <mass value="0.1593480327230531"/>
    <inertia ixx="6.4e-05" ixy="0.0" ixz="1.6e-05" iyy="0.000118" iyz="-2e-06" izz="6.6e-05"/>
  </inertial>
  <visual>
    <origin rpy="0 0 0" xyz="0.085363 0.243979 -0.615607"/>
    <geometry>
      <mesh filename="package://roomac_description/meshes/wrist_right_1.stl" scale="0.001 0.001 0.001"/>
    </geometry>
    <material name="silver"/>
  </visual>
  <collision>
    <origin rpy="0 0 0" xyz="0.085363 0.243979 -0.615607"/>
    <geometry>
      <mesh filename="package://roomac_description/meshes/wrist_right_1.stl" scale="0.001 0.001 0.001"/>
    </geometry>
  </collision>
</link>

<link name="gripper_right_1">
  <inertial>
    <origin rpy="0 0 0" xyz="0.0003095175801113986 0.0006959817920443867 -0.037223762933811466"/>
    <mass value="0.2826112434389509"/>
    <inertia ixx="0.000262" ixy="4e-06" ixz="7e-06" iyy="0.000181" iyz="-4e-06" izz="0.000107"/>
  </inertial>
  <visual>
    <origin rpy="0 0 0" xyz="0.111135 0.244052 -0.558565"/>
    <geometry>
      <mesh filename="package://roomac_description/meshes/gripper_right_1.stl" scale="0.001 0.001 0.001"/>
    </geometry>
    <material name="silver"/>
  </visual>
  <collision>
    <origin rpy="0 0 0" xyz="0.111135 0.244052 -0.558565"/>
    <geometry>
      <mesh filename="package://roomac_description/meshes/gripper_right_1.stl" scale="0.001 0.001 0.001"/>
    </geometry>
  </collision>
</link>

<link name="base_up_1">
  <inertial>
    <origin rpy="0 0 0" xyz="-0.08164752343563736 0.09519195325126116 0.3119048143118648"/>
    <mass value="8.208009817774046"/>
    <inertia ixx="0.304339" ixy="0.00025" ixz="0.003517" iyy="0.213566" iyz="0.005689" izz="0.145159"/>
  </inertial>
  <visual>
    <origin rpy="0 0 0" xyz="0.0595 0.102 -0.5415"/>
    <geometry>
      <mesh filename="package://roomac_description/meshes/base_up_1.stl" scale="0.001 0.001 0.001"/>
    </geometry>
    <material name="silver"/>
  </visual>
  <collision>
    <origin rpy="0 0 0" xyz="0.0595 0.102 -0.5415"/>
    <geometry>
      <mesh filename="package://roomac_description/meshes/base_up_1.stl" scale="0.001 0.001 0.001"/>
    </geometry>
  </collision>
</link>

<link name="head_1">
  <inertial>
    <origin rpy="0 0 0" xyz="-0.05136694488820312 0.08506464020920884 0.07263847989032413"/>
    <mass value="4.709471363871502"/>
    <inertia ixx="0.027707" ixy="0.000436" ixz="-0.002448" iyy="0.024831" iyz="0.00042" izz="0.016351"/>
  </inertial>
  <visual>
    <origin rpy="0 0 0" xyz="0.07765 0.087198 -0.981295"/>
    <geometry>
      <mesh filename="package://roomac_description/meshes/head_1.stl" scale="0.001 0.001 0.001"/>
    </geometry>
    <material name="silver"/>
  </visual>
  <collision>
    <origin rpy="0 0 0" xyz="0.07765 0.087198 -0.981295"/>
    <geometry>
      <mesh filename="package://roomac_description/meshes/head_1.stl" scale="0.001 0.001 0.001"/>
    </geometry>
  </collision>
</link>

<link name="left_wheel_hub_1">
  <inertial>
    <origin rpy="0 0 0" xyz="-1.7897652377030227e-06 -0.01271208905231394 3.109434602990291e-06"/>
    <mass value="0.094510942403721"/>
    <inertia ixx="5e-05" ixy="-0.0" ixz="0.0" iyy="8.5e-05" iyz="0.0" izz="5e-05"/>
  </inertial>
  <visual>
    <origin rpy="0 0 0" xyz="0.0 -0.2429 0.0"/>
    <geometry>
      <mesh filename="package://roomac_description/meshes/left_wheel_hub_1.stl" scale="0.001 0.001 0.001"/>
    </geometry>
    <material name="silver"/>
  </visual>
  <collision>
    <origin rpy="0 0 0" xyz="0.0 -0.2429 0.0"/>
    <geometry>
      <mesh filename="package://roomac_description/meshes/left_wheel_hub_1.stl" scale="0.001 0.001 0.001"/>
    </geometry>
  </collision>
</link>

<link name="left_caster_1">
  <inertial>
    <origin rpy="0 0 0" xyz="-0.020793104918766903 -0.0009180067931599534 -0.11995837555497461"/>
    <mass value="1.2807118618501256"/>
    <inertia ixx="0.001622" ixy="-2e-06" ixz="-0.000322" iyy="0.002002" iyz="-8e-06" izz="0.000685"/>
  </inertial>
  <visual>
    <origin rpy="0 0 0" xyz="0.2985 -0.16 -0.0275"/>
    <geometry>
      <mesh filename="package://roomac_description/meshes/left_caster_1.stl" scale="0.001 0.001 0.001"/>
    </geometry>
    <material name="silver"/>
  </visual>
  <collision>
    <origin rpy="0 0 0" xyz="0.2985 -0.16 -0.0275"/>
    <geometry>
      <mesh filename="package://roomac_description/meshes/left_caster_1.stl" scale="0.001 0.001 0.001"/>
    </geometry>
  </collision>
</link>


<link name="shoulder_left_1">
  <inertial>
    <origin rpy="0 0 0" xyz="-0.004712280699447291 0.04192792595665243 0.007911547381324269"/>
    <mass value="2.326205770355074"/>
    <inertia ixx="0.002632" ixy="0.000131" ixz="7.4e-05" iyy="0.002424" iyz="-0.000318" izz="0.002843"/>
  </inertial>
  <visual>
    <origin rpy="0 0 0" xyz="0.11 -0.144521 -0.9465"/>
    <geometry>
      <mesh filename="package://roomac_description/meshes/shoulder_left_1.stl" scale="0.001 0.001 0.001"/>
    </geometry>
    <material name="silver"/>
  </visual>
  <collision>
    <origin rpy="0 0 0" xyz="0.11 -0.144521 -0.9465"/>
    <geometry>
      <mesh filename="package://roomac_description/meshes/shoulder_left_1.stl" scale="0.001 0.001 0.001"/>
    </geometry>
  </collision>
</link>

<link name="shoulder_elbow_left_1">
  <inertial>
    <origin rpy="0 0 0" xyz="0.026664587620651853 2.1104869066257415e-07 -0.08367829742539012"/>
    <mass value="1.158628860891891"/>
    <inertia ixx="0.008424" ixy="0.0" ixz="-2.9e-05" iyy="0.00832" iyz="0.0" izz="0.000236"/>
  </inertial>
  <visual>
    <origin rpy="0 0 0" xyz="0.1365 -0.244021 -0.9465"/>
    <geometry>
      <mesh filename="package://roomac_description/meshes/shoulder_elbow_left_1.stl" scale="0.001 0.001 0.001"/>
    </geometry>
    <material name="silver"/>
  </visual>
  <collision>
    <origin rpy="0 0 0" xyz="0.1365 -0.244021 -0.9465"/>
    <geometry>
      <mesh filename="package://roomac_description/meshes/shoulder_elbow_left_1.stl" scale="0.001 0.001 0.001"/>
    </geometry>
  </collision>
</link>

<link name="elbow_wrist_left_1">
  <inertial>
    <origin rpy="0 0 0" xyz="-0.014013598483605477 0.0011767251849973404 -0.090479180057631"/>
    <mass value="0.623778609478909"/>
    <inertia ixx="0.001139" ixy="-0.0" ixz="-2.9e-05" iyy="0.001204" iyz="2e-05" izz="0.000118"/>
  </inertial>
  <visual>
    <origin rpy="0 0 0" xyz="0.094 -0.244021 -0.745425"/>
    <geometry>
      <mesh filename="package://roomac_description/meshes/elbow_wrist_left_1.stl" scale="0.001 0.001 0.001"/>
    </geometry>
    <material name="silver"/>
  </visual>
  <collision>
    <origin rpy="0 0 0" xyz="0.094 -0.244021 -0.745425"/>
    <geometry>
      <mesh filename="package://roomac_description/meshes/elbow_wrist_left_1.stl" scale="0.001 0.001 0.001"/>
    </geometry>
  </collision>
</link>

<link name="wrist_left_1">
  <inertial>
    <origin rpy="0 0 0" xyz="-0.026256916657696347 0.00089482633358276 -0.023441626539389637"/>
    <mass value="0.15934803272308629"/>
    <inertia ixx="6.4e-05" ixy="-0.0" ixz="1.6e-05" iyy="0.000118" iyz="2e-06" izz="6.6e-05"/>
  </inertial>
  <visual>
    <origin rpy="0 0 0" xyz="0.085363 -0.244021 -0.615607"/>
    <geometry>
      <mesh filename="package://roomac_description/meshes/wrist_left_1.stl" scale="0.001 0.001 0.001"/>
    </geometry>
    <material name="silver"/>
  </visual>
  <collision>
    <origin rpy="0 0 0" xyz="0.085363 -0.244021 -0.615607"/>
    <geometry>
      <mesh filename="package://roomac_description/meshes/wrist_left_1.stl" scale="0.001 0.001 0.001"/>
    </geometry>
  </collision>
</link>

<link name="gripper_left_1">
  <inertial>
    <origin rpy="0 0 0" xyz="0.00030951758007047303 -0.0006959118539851539 -0.037223762933813465"/>
    <mass value="0.2826112434389101"/>
    <inertia ixx="0.000262" ixy="-4e-06" ixz="7e-06" iyy="0.000181" iyz="4e-06" izz="0.000107"/>
  </inertial>
  <visual>
    <origin rpy="0 0 0" xyz="0.111135 -0.244094 -0.558565"/>
    <geometry>
      <mesh filename="package://roomac_description/meshes/gripper_left_1.stl" scale="0.001 0.001 0.001"/>
    </geometry>
    <material name="silver"/>
  </visual>
  <collision>
    <origin rpy="0 0 0" xyz="0.111135 -0.244094 -0.558565"/>
    <geometry>
      <mesh filename="package://roomac_description/meshes/gripper_left_1.stl" scale="0.001 0.001 0.001"/>
    </geometry>
  </collision>
</link>

<link name="right_wheel_1">
  <inertial>
    <origin rpy="0 0 0" xyz="-2.974771888375471e-08 -0.04399999555411241 -4.4329110293617185e-09"/>
    <mass value="3.114307134470504"/>
    <inertia ixx="0.020129" ixy="-0.0" ixz="0.0" iyy="0.038769" iyz="-0.0" izz="0.020129"/>
  </inertial>
  <visual>
    <origin rpy="0 0 0" xyz="-0.0 0.2099 0.0"/>
    <geometry>
      <mesh filename="package://roomac_description/meshes/right_wheel_1.stl" scale="0.001 0.001 0.001"/>
    </geometry>
    <material name="silver"/>
  </visual>
  <collision>
    <origin rpy="0 0 0" xyz="-0.0 0.2099 0.0"/>
    <geometry>
      <mesh filename="package://roomac_description/meshes/right_wheel_1.stl" scale="0.001 0.001 0.001"/>
    </geometry>
  </collision>
</link>

<link name="left_wheel_1">
  <inertial>
    <origin rpy="0 0 0" xyz="-1.510251436798171e-08 0.043999994793375324 7.652163045435145e-09"/>
    <mass value="3.114308964744888"/>
    <inertia ixx="0.020129" ixy="0.0" ixz="0.0" iyy="0.038769" iyz="0.0" izz="0.020129"/>
  </inertial>
  <visual>
    <origin rpy="0 0 0" xyz="0.0 -0.2099 -0.0"/>
    <geometry>
      <mesh filename="package://roomac_description/meshes/left_wheel_1.stl" scale="0.001 0.001 0.001"/>
    </geometry>
    <material name="silver"/>
  </visual>
  <collision>
    <origin rpy="0 0 0" xyz="0.0 -0.2099 -0.0"/>
    <geometry>
      <mesh filename="package://roomac_description/meshes/left_wheel_1.stl" scale="0.001 0.001 0.001"/>
    </geometry>
  </collision>
</link>

<joint name="right_wheel_hub" type="fixed">
  <origin rpy="0 0 0" xyz="0.0 -0.033 0.0"/>
  <parent link="right_wheel_1"/>
  <child link="right_wheel_hub_1"/>
</joint>

<joint name="right_caster" type="fixed">
  <origin rpy="0 0 0" xyz="-0.2985 -0.16 0.0275"/>
  <parent link="base_link"/>
  <child link="right_caster_1"/>
</joint>

<joint name="right_shoulder_pan" type="continuous">
  <origin rpy="0 0 0" xyz="-0.0505 -0.042479 0.405"/>
  <parent link="base_up_1"/>
  <child link="shoulder_right_1"/>
  <axis xyz="0.0 -1.0 -0.0"/>
</joint>

<joint name="right_shoulder_lift" type="continuous">
  <origin rpy="0 0 0" xyz="-0.0265 -0.0995 0.0"/>
  <parent link="shoulder_right_1"/>
  <child link="shoulder_elbow_right_1"/>
  <axis xyz="1.0 0.0 -0.0"/>
</joint>

<joint name="right_elbow" type="continuous">
  <origin rpy="0 0 0" xyz="0.0425 0.0 -0.201075"/>
  <parent link="shoulder_elbow_right_1"/>
  <child link="elbow_wrist_right_1"/>
  <axis xyz="1.0 0.0 -0.0"/>
</joint>

<joint name="right_wrist" type="continuous">
  <origin rpy="0 0 0" xyz="0.008637 0.0 -0.129818"/>
  <parent link="elbow_wrist_right_1"/>
  <child link="wrist_right_1"/>
  <axis xyz="-1.0 -0.0 0.0"/>
</joint>

<joint name="right_gripper_twist" type="continuous">
  <origin rpy="0 0 0" xyz="-0.025772 -7.3e-05 -0.057042"/>
  <parent link="wrist_right_1"/>
  <child link="gripper_right_1"/>
  <axis xyz="-0.0 0.0 -1.0"/>
</joint>

<joint name="up_base" type="fixed">
  <origin rpy="0 0 0" xyz="-0.0595 -0.102 0.5415"/>
  <parent link="base_link"/>
  <child link="base_up_1"/>
</joint>

<joint name="head" type="fixed">
  <origin rpy="0 0 0" xyz="-0.01815 0.014802 0.439795"/>
  <parent link="base_up_1"/>
  <child link="head_1"/>
</joint>

<joint name="left_wheel_hub" type="fixed">
  <origin rpy="0 0 0" xyz="0.0 0.033 -0.0"/>
  <parent link="left_wheel_1"/>
  <child link="left_wheel_hub_1"/>
</joint>

<joint name="left_caster" type="fixed">
  <origin rpy="0 0 0" xyz="-0.2985 0.16 0.0275"/>
  <parent link="base_link"/>
  <child link="left_caster_1"/>
</joint>

<joint name="left_shoulder_pan" type="continuous">
  <origin rpy="0 0 0" xyz="-0.0505 0.246521 0.405"/>
  <parent link="base_up_1"/>
  <child link="shoulder_left_1"/>
  <axis xyz="0.0 -1.0 -0.0"/>
</joint>

<joint name="left_shoulder_lift" type="continuous">
  <origin rpy="0 0 0" xyz="-0.0265 0.0995 0.0"/>
  <parent link="shoulder_left_1"/>
  <child link="shoulder_elbow_left_1"/>
  <axis xyz="-1.0 -0.0 0.0"/>
</joint>

<joint name="left_elbow" type="continuous">
  <origin rpy="0 0 0" xyz="0.0425 0.0 -0.201075"/>
  <parent link="shoulder_elbow_left_1"/>
  <child link="elbow_wrist_left_1"/>
  <axis xyz="1.0 0.0 -0.0"/>
</joint>

<joint name="left_wrist" type="continuous">
  <origin rpy="0 0 0" xyz="0.008637 0.0 -0.129818"/>
  <parent link="elbow_wrist_left_1"/>
  <child link="wrist_left_1"/>
  <axis xyz="1.0 0.0 -0.0"/>
</joint>

<joint name="left_gripper_twist" type="continuous">
  <origin rpy="0 0 0" xyz="-0.025772 7.3e-05 -0.057042"/>
  <parent link="wrist_left_1"/>
  <child link="gripper_left_1"/>
  <axis xyz="0.0 0.0 1.0"/>
</joint>

<joint name="right_wheel" type="continuous">
  <origin rpy="0 0 0" xyz="0.0 -0.2099 0.0"/>
  <parent link="base_link"/>
  <child link="right_wheel_1"/>
  <axis xyz="0.0 -1.0 -0.0"/>
</joint>

<joint name="left_wheel" type="continuous">
  <origin rpy="0 0 0" xyz="0.0 0.2099 0.0"/>
  <parent link="base_link"/>
  <child link="left_wheel_1"/>
  <axis xyz="-0.0 1.0 0.0"/>
</joint>

<joint name="kinect_joint" type="fixed">
		<origin rpy="0 ${(31.513/180.)*pi} 0" xyz="-0.108561 0.039543 0.479024"/>
		<parent link="base_link"/>
		<child link="camera_link"/>
</joint>
<link name="camera_link" />

</robot>
